Workbook
Name Slicer_Department_Name: #N/A
Name Slicer_EmploymentStatus: #N/A
Name Slicer_Performance_Band: #N/A

Sheet Raw_Employee_Data
A1: EMP ID | B1: First_Name | C1: Last_Name | D1: Full Name | E1: DeptCode | F1: Hire Date | G1: Salary | H1: Perf_Score | I1: EmploymentStatus | J1: Department Name | K1: Year of Sevice | L1: Performance Band | M1: Eligible Bonus Amount
A2: EMP127 | B2: Emily | C2: Brown | D2: =CONCATENATE(B2," ",C2) -> Emily Brown | E2: IT02 | F2: 43093 | G2: 50361 | H2: 52 | I2: Active | J2: =VLOOKUP(E2,Lookup_Departments!$A$1:$B$7,2,FALSE) -> Information Technology | K2: =YEAR(TODAY())-YEAR(F:F) -> 9 | L2: =VLOOKUP(H2,Lookup_Performance!$A$1:$D$6,3,TRUE) -> Developing | M2: =G2*VLOOKUP(H2,Lookup_Performance!$A$1:$D$6,4,TRUE) -> 1007.22
A3: EMP046 | B3: Richard | C3: Hernandez | D3: =CONCATENATE(B3," ",C3) -> Richard Hernandez | E3: MKT04 | F3: 44659 | G3: 112673 | H3: 70 | I3: Active | J3: =VLOOKUP(E3,Lookup_Departments!$A$1:$B$7,2,FALSE) -> Marketing | K3: =YEAR(TODAY())-YEAR(F:F) -> 4 | L3: =VLOOKUP(H3,Lookup_Performance!$A$1:$D$6,3,TRUE) -> Achieving | M3: =G3*VLOOKUP(H3,Lookup_Performance!$A$1:$D$6,4,TRUE) -> 5633.65
A4: EMP134 | B4: Emily | C4: Gonzalez | D4: =CONCATENATE(B4," ",C4) -> Emily Gonzalez | E4: IT02 | F4: 42431 | G4: 114425 | H4: 54 | I4: Left | J4: =VLOOKUP(E4,Lookup_Departments!$A$1:$B$7,2,FALSE) -> Information Technology | K4: =YEAR(TODAY())-YEAR(F:F) -> 10 | L4: =VLOOKUP(H4,Lookup_Performance!$A$1:$D$6,3,TRUE) -> Developing | M4: =G4*VLOOKUP(H4,Lookup_Performance!$A$1:$D$6,4,TRUE) -> 2288.5 | O4: =SUM(M:M) -> 505914.21
A5: EMP139 | B5: John | C5: Martinez | D5: =CONCATENATE(B5," ",C5) -> John Martinez | E5: FIN03 | F5: 45110 | G5: 103831 | H5: 70 | I5: Active | J5: =VLOOKUP(E5,Lookup_Departments!$A$1:$B$7,2,FALSE) -> Finance | K5: =YEAR(TODAY())-YEAR(F:F) -> 3 | L5: =VLOOKUP(H5,Lookup_Performance!$A$1:$D$6,3,TRUE) -> Achieving | M5: =G5*VLOOKUP(H5,Lookup_Performance!$A$1:$D$6,4,TRUE) -> 5191.55 | O5: =SUM(M:M) -> 505914.21
A6: EMP112 | B6: Thomas | C6: Smith | D6: =CONCATENATE(B6," ",C6) -> Thomas Smith | E6: IT02 | F6: 44977 | G6: 73785 | H6: 40 | I6: Left | J6: =VLOOKUP(E6,Lookup_Departments!$A$1:$B$7,2,FALSE) -> Information Technology | K6: =YEAR(TODAY())-YEAR(F:F) -> 3 | L6: =VLOOKUP(H6,Lookup_Performance!$A$1:$D$6,3,TRUE) -> Needs Improvement | M6: =G6*VLOOKUP(H6,Lookup_Performance!$A$1:$D$6,4,TRUE) -> 0
A7: EMP030 | B7: Emily | C7: Johnson | D7: =CONCATENATE(B7," ",C7) -> Emily Johnson | E7: OPS06 | F7: 37335 | G7: 115882 | H7: 49 | I7: Active | J7: =VLOOKUP(E7,Lookup_Departments!$A$1:$B$7,2,FALSE) -> Operations | K7: =YEAR(TODAY())-YEAR(F:F) -> 24 | L7: =VLOOKUP(H7,Lookup_Performance!$A$1:$D$6,3,TRUE) -> Needs Improvement | M7: =G7*VLOOKUP(H7,Lookup_Performance!$A$1:$D$6,4,TRUE) -> 0
A8: EMP096 | B8: John | C8: Wilson | D8: =CONCATENATE(B8," ",C8) -> John Wilson | E8: OPS06 | F8: 45272 | G8: 59980 | H8: 70 | I8: Left | J8: =VLOOKUP(E8,Lookup_Departments!$A$1:$B$7,2,FALSE) -> Operations | K8: =YEAR(TODAY())-YEAR(F:F) -> 3 | L8: =VLOOKUP(H8,Lookup_Performance!$A$1:$D$6,3,TRUE) -> Achieving | M8: =G8*VLOOKUP(H8,Lookup_Performance!$A$1:$D$6,4,TRUE) -> 2999
A9: EMP098 | B9: Jessica | C9: Smith | D9: =CONCATENATE(B9," ",C9) -> Jessica Smith | E9: OPS06 | F9: 44174 | G9: 68728 | H9: 45 | I9: Active | J9: =VLOOKUP(E9,Lookup_Departments!$A$1:$B$7,2,FALSE) -> Operations | K9: =YEAR(TODAY())-YEAR(F:F) -> 6 | L9: =VLOOKUP(H9,Lookup_Performance!$A$1:$D$6,3,TRUE) -> Needs Improvement | M9: =G9*VLOOKUP(H9,Lookup_Performance!$A$1:$D$6,4,TRUE) -> 0
A10: EMP095 | C10: Rodriguez | D10: =CONCATENATE(B10," ",C10) -> Rodriguez | E10: FIN03 | F10: 43107 | G10: 102139 | H10: 79 | I10: Active | J10: =VLOOKUP(E10,Lookup_Departments!$A$1:$B$7,2,FALSE) -> Finance | K10: =YEAR(TODAY())-YEAR(F:F) -> 8 | L10: =VLOOKUP(H10,Lookup_Performance!$A$1:$D$6,3,TRUE) -> Achieving | M10: =G10*VLOOKUP(H10,Lookup_Performance!$A$1:$D$6,4,TRUE) -> 5106.95
A11: EMP140 | B11: Michael | C11: Martinez | D11: =CONCATENATE(B11," ",C11) -> Michael Martinez | E11: SAL05 | F11: 42676 | G11: 94998 | H11: 58 | I11: Active | J11: =VLOOKUP(E11,Lookup_Departments!$A$1:$B$7,2,FALSE) -> Sales | K11: =YEAR(TODAY())-YEAR(F:F) -> 10 | L11: =VLOOKUP(H11,Lookup_Performance!$A$1:$D$6,3,TRUE) -> Developing | M11: =G11*VLOOKUP(H11,Lookup_Performance!$A$1:$D$6,4,TRUE) -> 1899.96
A12: EMP020 | B12: Emily | C12: Miller | D12: =CONCATENATE(B12," ",C12) -> Emily Miller | E12: SAL05 | F12: 43911 | G12: 118635 | H12: 49 | I12: Active | J12: =VLOOKUP(E12,Lookup_Departments!$A$1:$B$7,2,FALSE) -> Sales | K12: =YEAR(TODAY())-YEAR(F:F) -> 6 | L12: =VLOOKUP(H12,Lookup_Performance!$A$1:$D$6,3,TRUE) -> Needs Improvement | M12: =G12*VLOOKUP(H12,Lookup_Performance!$A$1:$D$6,4,TRUE) -> 0 | O12: =AVERAGE(G:G) -> 83485.197
A13: EMP057 | B13: Emily | C13: Hernandez | D13: =CONCATENATE(B13," ",C13) -> Emily Hernandez | E13: IT02 | F13: 42425 | G13: 76918 | H13: 62 | I13: Active | J13: =VLOOKUP(E13,Lookup_Departments!$A$1:$B$7,2,FALSE) -> Information Technology | K13: =YEAR(TODAY())-YEAR(F:F) -> 10 | L13: =VLOOKUP(H13,Lookup_Performance!$A$1:$D$6,3,TRUE) -> Developing | M13: =G13*VLOOKUP(H13,Lookup_Performance!$A$1:$D$6,4,TRUE) -> 1538.36
A14: EMP016 | B14: Jane | C14: Williams | D14: =CONCATENATE(B14," ",C14) -> Jane Williams | E14: MKT04 | F14: 42907 | G14: 61408 | H14: 48 | I14: Active | J14: =VLOOKUP(E14,Lookup_Departments!$A$1:$B$7,2,FALSE) -> Marketing | K14: =YEAR(TODAY())-YEAR(F:F) -> 9 | L14: =VLOOKUP(H14,Lookup_Performance!$A$1:$D$6,3,TRUE) -> Needs Improvement | M14: =G14*VLOOKUP(H14,Lookup_Performance!$A$1:$D$6,4,TRUE) -> 0 | O14: =MEDIAN(H:H) -> 70
A15: EMP070 | B15: Jane | C15: Miller | D15: =CONCATENATE(B15," ",C15) -> Jane Miller | E15: MKT04 | F15: 44001 | G15: 99990 | H15: 54 | I15: Active | J15: =VLOOKUP(E15,Lookup_Departments!$A$1:$B$7,2,FALSE) -> Marketing | K15: =YEAR(TODAY())-YEAR(F:F) -> 6 | L15: =VLOOKUP(H15,Lookup_Performance!$A$1:$D$6,3,TRUE) -> Developing | M15: =G15*VLOOKUP(H15,Lookup_Performance!$A$1:$D$6,4,TRUE) -> 1999.8
A16: EMP025 | B16: Robert | C16: Jones | D16: =CONCATENATE(B16," ",C16) -> Robert Jones | E16: MKT04 | F16: 43820 | G16: 80385 | H16: 70 | I16: Active | J16: =VLOOKUP(E16,Lookup_Departments!$A$1:$B$7,2,FALSE) -> Marketing | K16: =YEAR(TODAY())-YEAR(F:F) -> 7 | L16: =VLOOKUP(H16,Lookup_Performance!$A$1:$D$6,3,TRUE) -> Achieving | M16: =G16*VLOOKUP(H16,Lookup_Performance!$A$1:$D$6,4,TRUE) -> 4019.25
A17: EMP031 | B17: Thomas | C17: Rodriguez | D17: =CONCATENATE(B17," ",C17) -> Thomas Rodriguez | E17: SAL05 | F17: 45169 | G17: 65290 | H17: 77 | I17: Active | J17: =VLOOKUP(E17,Lookup_Departments!$A$1:$B$7,2,FALSE) -> Sales | K17: =YEAR(TODAY())-YEAR(F:F) -> 3 | L17: =VLOOKUP(H17,Lookup_Performance!$A$1:$D$6,3,TRUE) -> Achieving | M17: =G17*VLOOKUP(H17,Lookup_Performance!$A$1:$D$6,4,TRUE) -> 3264.5
A18: EMP126 | B18: Emily | C18: Davis | D18: =CONCATENATE(B18," ",C18) -> Emily Davis | E18: IT02 | F18: 42337 | G18: 105765 | H18: 42 | I18: Active | J18: =VLOOKUP(E18,Lookup_Departments!$A$1:$B$7,2,FALSE) -> Information Technology | K18: =YEAR(TODAY())-YEAR(F:F) -> 11 | L18: =VLOOKUP(H18,Lookup_Performance!$A$1:$D$6,3,TRUE) -> Needs Improvement | M18: =G18*VLOOKUP(H18,Lookup_Performance!$A$1:$D$6,4,TRUE) -> 0
A19: EMP109 | B19: James | C19: Martinez | D19: =CONCATENATE(B19," ",C19) -> James Martinez | E19: SAL05 | F19: 42899 | G19: 102921 | H19: 49 | I19: Active | J19: =VLOOKUP(E19,Lookup_Departments!$A$1:$B$7,2,FALSE) -> Sales | K19: =YEAR(TODAY())-YEAR(F:F) -> 9 | L19: =VLOOKUP(H19,Lookup_Performance!$A$1:$D$6,3,TRUE) -> Needs Improvement | M19: =G19*VLOOKUP(H19,Lookup_Performance!$A$1:$D$6,4,TRUE) -> 0
A20: EMP066 | B20: Ashley | C20: Lopez | D20: =CONCATENATE(B20," ",C20) -> Ashley Lopez | E20: MKT04 | F20: 43235 | G20: 73984 | H20: 93 | I20: Active | J20: =VLOOKUP(E20,Lookup_Departments!$A$1:$B$7,2,FALSE) -> Marketing | K20: =YEAR(TODAY())-YEAR(F:F) -> 8 | L20: =VLOOKUP(H20,Lookup_Performance!$A$1:$D$6,3,TRUE) -> Exceeding | M20: =G20*VLOOKUP(H20,Lookup_Performance!$A$1:$D$6,4,TRUE) -> 5918.72
A21: EMP120 | B21: Amanda | C21: Gonzalez | D21: =CONCATENATE(B21," ",C21) -> Amanda Gonzalez | E21: IT02 | F21: 42575 | G21: 82713.43 | H21: 75 | I21: Active | J21: =VLOOKUP(E21,Lookup_Departments!$A$1:$B$7,2,FALSE) -> Information Technology | K21: =YEAR(TODAY())-YEAR(F:F) -> 10 | L21: =VLOOKUP(H21,Lookup_Performance!$A$1:$D$6,3,TRUE) -> Achieving | M21: =G21*VLOOKUP(H21,Lookup_Performance!$A$1:$D$6,4,TRUE) -> 4135.6715
A22: EMP019 | B22: Michael | C22: Hernandez | D22: =CONCATENATE(B22," ",C22) -> Michael Hernandez | E22: FIN03 | F22: 43076 | G22: 118527 | H22: 50 | I22: Active | J22: =VLOOKUP(E22,Lookup_Departments!$A$1:$B$7,2,FALSE) -> Finance | K22: =YEAR(TODAY())-YEAR(F:F) -> 9 | L22: =VLOOKUP(H22,Lookup_Performance!$A$1:$D$6,3,TRUE) -> Developing | M22: =G22*VLOOKUP(H22,Lookup_Performance!$A$1:$D$6,4,TRUE) -> 2370.54
A23: EMP013 | B23: Richard | C23: Hernandez | D23: =CONCATENATE(B23," ",C23) -> Richard Hernandez | E23: MKT04 | F23: 44353 | G23: 107871 | H23: 88 | I23: Active | J23: =VLOOKUP(E23,Lookup_Departments!$A$1:$B$7,2,FALSE) -> Marketing | K23: =YEAR(TODAY())-YEAR(F:F) -> 5 | L23: =VLOOKUP(H23,Lookup_Performance!$A$1:$D$6,3,TRUE) -> Exceeding | M23: =G23*VLOOKUP(H23,Lookup_Performance!$A$1:$D$6,4,TRUE) -> 8629.68
A24: EMP010 | B24: Michael | C24: Rodriguez | D24: =CONCATENATE(B24," ",C24) -> Michael Rodriguez | E24: IT02 | F24: 44815 | G24: 93956 | H24: 50 | I24: Left | J24: =VLOOKUP(E24,Lookup_Departments!$A$1:$B$7,2,FALSE) -> Information Technology | K24: =YEAR(TODAY())-YEAR(F:F) -> 4 | L24: =VLOOKUP(H24,Lookup_Performance!$A$1:$D$6,3,TRUE) -> Developing | M24: =G24*VLOOKUP(H24,Lookup_Performance!$A$1:$D$6,4,TRUE) -> 1879.12
A25: EMP032 | B25: Jessica | C25: Johnson | D25: =CONCATENATE(B25," ",C25) -> Jessica Johnson | E25: FIN03 | F25: 42565 | G25: 100851 | H25: 64 | I25: Active | J25: =VLOOKUP(E25,Lookup_Departments!$A$1:$B$7,2,FALSE) -> Finance | K25: =YEAR(TODAY())-YEAR(F:F) -> 10 | L25: =VLOOKUP(H25,Lookup_Performance!$A$1:$D$6,3,TRUE) -> Developing | M25: =G25*VLOOKUP(H25,Lookup_Performance!$A$1:$D$6,4,TRUE) -> 2017.02
A26: EMP082 | B26: Ashley | C26: Williams | D26: =CONCATENATE(B26," ",C26) -> Ashley Williams | E26: SAL05 | F26: 44728 | G26: 68655 | H26: 32 | I26: Active | J26: =VLOOKUP(E26,Lookup_Departments!$A$1:$B$7,2,FALSE) -> Sales | K26: =YEAR(TODAY())-YEAR(F:F) -> 4 | L26: =VLOOKUP(H26,Lookup_Performance!$A$1:$D$6,3,TRUE) -> Needs Improvement | M26: =G26*VLOOKUP(H26,Lookup_Performance!$A$1:$D$6,4,TRUE) -> 0
A27: EMP052 | C27: Williams | D27: =CONCATENATE(B27," ",C27) -> Williams | E27: SAL05 | F27: 45134 | G27: 81205 | H27: 59 | I27: Active | J27: =VLOOKUP(E27,Lookup_Departments!$A$1:$B$7,2,FALSE) -> Sales | K27: =YEAR(TODAY())-YEAR(F:F) -> 3 | L27: =VLOOKUP(H27,Lookup_Performance!$A$1:$D$6,3,TRUE) -> Developing | M27: =G27*VLOOKUP(H27,Lookup_Performance!$A$1:$D$6,4,TRUE) -> 1624.1
A28: EMP129 | B28: John | C28: Wilson | D28: =CONCATENATE(B28," ",C28) -> John Wilson | E28: SAL05 | F28: 43732 | G28: 77610 | H28: 88 | I28: Active | J28: =VLOOKUP(E28,Lookup_Departments!$A$1:$B$7,2,FALSE) -> Sales | K28: =YEAR(TODAY())-YEAR(F:F) -> 7 | L28: =VLOOKUP(H28,Lookup_Performance!$A$1:$D$6,3,TRUE) -> Exceeding | M28: =G28*VLOOKUP(H28,Lookup_Performance!$A$1:$D$6,4,TRUE) -> 6208.8
A29: EMP146 | B29: Thomas | C29: Rodriguez | D29: =CONCATENATE(B29," ",C29) -> Thomas Rodriguez | E29: IT02 | F29: 44765 | G29: 50873 | H29: 90 | I29: Active | J29: =VLOOKUP(E29,Lookup_Departments!$A$1:$B$7,2,FALSE) -> Information Technology | K29: =YEAR(TODAY())-YEAR(F:F) -> 4 | L29: =VLOOKUP(H29,Lookup_Performance!$A$1:$D$6,3,TRUE) -> Exceeding | M29: =G29*VLOOKUP(H29,Lookup_Performance!$A$1:$D$6,4,TRUE) -> 4069.84
A30: EMP099 | B30: Michael | C30: Wilson | D30: =CONCATENATE(B30," ",C30) -> Michael Wilson | E30: FIN03 | F30: 41412 | G30: 85312 | H30: 66 | I30: Active | J30: =VLOOKUP(E30,Lookup_Departments!$A$1:$B$7,2,FALSE) -> Finance | K30: =YEAR(TODAY())-YEAR(F:F) -> 13 | L30: =VLOOKUP(H30,Lookup_Performance!$A$1:$D$6,3,TRUE) -> Developing | M30: =G30*VLOOKUP(H30,Lookup_Performance!$A$1:$D$6,4,TRUE) -> 1706.24
A31: EMP015 | B31: John | C31: Rodriguez | D31: =CONCATENATE(B31," ",C31) -> John Rodriguez | E31: SAL05 | F31: 42202 | G31: 82713.43 | H31: 68 | I31: Active | J31: =VLOOKUP(E31,Lookup_Departments!$A$1:$B$7,2,FALSE) -> Sales | K31: =YEAR(TODAY())-YEAR(F:F) -> 11 | L31: =VLOOKUP(H31,Lookup_Performance!$A$1:$D$6,3,TRUE) -> Developing | M31: =G31*VLOOKUP(H31,Lookup_Performance!$A$1:$D$6,4,TRUE) -> 1654.2686
A32: EMP076 | B32: Thomas | C32: Hernandez | D32: =CONCATENATE(B32," ",C32) -> Thomas Hernandez | E32: OPS06 | F32: 38579 | G32: 97055 | H32: 80 | I32: Active | J32: =VLOOKUP(E32,Lookup_Departments!$A$1:$B$7,2,FALSE) -> Operations | K32: =YEAR(TODAY())-YEAR(F:F) -> 21 | L32: =VLOOKUP(H32,Lookup_Performance!$A$1:$D$6,3,TRUE) -> Achieving | M32: =G32*VLOOKUP(H32,Lookup_Performance!$A$1:$D$6,4,TRUE) -> 4852.75
A33: EMP137 | B33: Michael | C33: Johnson | D33: =CONCATENATE(B33," ",C33) -> Michael Johnson | E33: IT02 | F33: 45195 | G33: 66069 | H33: 72 | I33: Active | J33: =VLOOKUP(E33,Lookup_Departments!$A$1:$B$7,2,FALSE) -> Information Technology | K33: =YEAR(TODAY())-YEAR(F:F) -> 3 | L33: =VLOOKUP(H33,Lookup_Performance!$A$1:$D$6,3,TRUE) -> Achieving | M33: =G33*VLOOKUP(H33,Lookup_Performance!$A$1:$D$6,4,TRUE) -> 3303.45
A34: EMP056 | B34: Sarah | C34: Brown | D34: =CONCATENATE(B34," ",C34) -> Sarah Brown | E34: IT02 | F34: 40348 | G34: 90157 | H34: 58 | I34: Active | J34: =VLOOKUP(E34,Lookup_Departments!$A$1:$B$7,2,FALSE) -> Information Technology | K34: =YEAR(TODAY())-YEAR(F:F) -> 16 | L34: =VLOOKUP(H34,Lookup_Performance!$A$1:$D$6,3,TRUE) -> Developing | M34: =G34*VLOOKUP(H34,Lookup_Performance!$A$1:$D$6,4,TRUE) -> 1803.14
A35: EMP125 | B35: Jane | C35: Martinez | D35: =CONCATENATE(B35," ",C35) -> Jane Martinez | E35: HR01 | F35: 44578 | G35: 59899 | H35: 78 | I35: Active | J35: =VLOOKUP(E35,Lookup_Departments!$A$1:$B$7,2,FALSE) -> Human Resources | K35: =YEAR(TODAY())-YEAR(F:F) -> 4 | L35: =VLOOKUP(H35,Lookup_Performance!$A$1:$D$6,3,TRUE) -> Achieving | M35: =G35*VLOOKUP(H35,Lookup_Performance!$A$1:$D$6,4,TRUE) -> 2994.95
A36: EMP085 | B36: Emily | C36: Jones | D36: =CONCATENATE(B36," ",C36) -> Emily Jones | E36: FIN03 | F36: 37819 | G36: 113389 | H36: 30 | I36: Active | J36: =VLOOKUP(E36,Lookup_Departments!$A$1:$B$7,2,FALSE) -> Finance | K36: =YEAR(TODAY())-YEAR(F:F) -> 23 | L36: =VLOOKUP(H36,Lookup_Performance!$A$1:$D$6,3,TRUE) -> Needs Improvement | M36: =G36*VLOOKUP(H36,Lookup_Performance!$A$1:$D$6,4,TRUE) -> 0
A37: EMP106 | C37: Brown | D37: =CONCATENATE(B37," ",C37) -> Brown | E37: IT02 | F37: 37149 | G37: 102691 | H37: 52 | I37: Active | J37: =VLOOKUP(E37,Lookup_Departments!$A$1:$B$7,2,FALSE) -> Information Technology | K37: =YEAR(TODAY())-YEAR(F:F) -> 25 | L37: =VLOOKUP(H37,Lookup_Performance!$A$1:$D$6,3,TRUE) -> Developing | M37: =G37*VLOOKUP(H37,Lookup_Performance!$A$1:$D$6,4,TRUE) -> 2053.82
A38: EMP043 | B38: John | C38: Wilson | D38: =CONCATENATE(B38," ",C38) -> John Wilson | E38: OPS06 | F38: 37855 | G38: 111845 | H38: 98 | I38: Active | J38: =VLOOKUP(E38,Lookup_Departments!$A$1:$B$7,2,FALSE) -> Operations | K38: =YEAR(TODAY())-YEAR(F:F) -> 23 | L38: =VLOOKUP(H38,Lookup_Performance!$A$1:$D$6,3,TRUE) -> Outstanding | M38: =G38*VLOOKUP(H38,Lookup_Performance!$A$1:$D$6,4,TRUE) -> 13421.4
A39: EMP068 | B39: Melissa | C39: Brown | D39: =CONCATENATE(B39," ",C39) -> Melissa Brown | E39: SAL05 | F39: 44741 | G39: 69219 | H39: 93 | I39: Active | J39: =VLOOKUP(E39,Lookup_Departments!$A$1:$B$7,2,FALSE) -> Sales | K39: =YEAR(TODAY())-YEAR(F:F) -> 4 | L39: =VLOOKUP(H39,Lookup_Performance!$A$1:$D$6,3,TRUE) -> Exceeding | M39: =G39*VLOOKUP(H39,Lookup_Performance!$A$1:$D$6,4,TRUE) -> 5537.52
A40: EMP128 | B40: Michael | C40: Smith | D40: =CONCATENATE(B40," ",C40) -> Michael Smith | E40: FIN03 | F40: 43949 | G40: 82713.43 | H40: 80 | I40: Left | J40: =VLOOKUP(E40,Lookup_Departments!$A$1:$B$7,2,FALSE) -> Finance | K40: =YEAR(TODAY())-YEAR(F:F) -> 6 | L40: =VLOOKUP(H40,Lookup_Performance!$A$1:$D$6,3,TRUE) -> Achieving | M40: =G40*VLOOKUP(H40,Lookup_Performance!$A$1:$D$6,4,TRUE) -> 4135.6715
...

Sheet Analysis
G2: Row Labels | H2: Count of EMP ID
A3: Count of EMP ID | B3: Average of Salary | G3: Finance | H3: 17
A4: 150 | B4: 83485.197 | G4: Human Resources | H4: 18
G5: Information Technology | H5: 36
G6: Marketing | H6: 19
G7: Operations | H7: 29
A8: Count of EmploymentStatus | B8: Column Labels | G8: Sales | H8: 31
A9: Row Labels | B9: Active | C9: Left | D9: Resigned | E9: Grand Total | G9: Grand Total | H9: 150
A10: Finance | B10: 14 | C10: 3 | E10: 17
A11: Human Resources | B11: 15 | C11: 2 | D11: 1 | E11: 18
A12: Information Technology | B12: 28 | C12: 6 | D12: 2 | E12: 36 | G12: Row Labels | H12: Count of EmploymentStatus
A13: Marketing | B13: 16 | C13: 3 | E13: 19 | G13: Finance | H13: 17
A14: Operations | B14: 18 | C14: 6 | D14: 5 | E14: 29 | G14: Human Resources | H14: 18
A15: Sales | B15: 25 | C15: 4 | D15: 2 | E15: 31 | G15: Information Technology | H15: 36
A16: Grand Total | B16: 116 | C16: 24 | D16: 10 | E16: 150 | G16: Marketing | H16: 19
G17: Operations | H17: 29
G18: Sales | H18: 31
G19: Grand Total | H19: 150
A20: Row Labels | B20: Average of Perf_Score
A21: Active | B21: 67.862069 | E21: Count of EmploymentStatus | F21: Column Labels
A22: Left | B22: 66.291667 | E22: Row Labels | F22: Active | G22: Left | H22: Resigned | I22: Grand Total | J22: Attrition Rate
A23: Resigned | B23: 76.4 | E23: Finance | F23: 14 | G23: 3 | I23: 17 | J23: =G23/I23 -> 0.17647059
A24: Grand Total | B24: 68.18 | E24: Human Resources | F24: 15 | G24: 2 | H24: 1 | I24: 18 | J24: =G24/I24 -> 0.11111111
E25: Information Technology | F25: 28 | G25: 6 | H25: 2 | I25: 36 | J25: =G25/I25 -> 0.16666667
E26: Marketing | F26: 16 | G26: 3 | I26: 19 | J26: =G26/I26 -> 0.15789474
E27: Operations | F27: 18 | G27: 6 | H27: 5 | I27: 29 | J27: =G27/I27 -> 0.20689655
A28: Row Labels | B28: Sum of Eligible Bonus Amount | E28: Sales | F28: 25 | G28: 4 | H28: 2 | I28: 31 | J28: =G28/I28 -> 0.12903226
A29: Achieving | B29: 197690.16 | E29: Grand Total | F29: 116 | G29: 24 | H29: 10 | I29: 150 | J29: =G29/I29 -> 0.16
A30: Developing | B30: 71372.449
A31: Exceeding | B31: 144546.95
A32: Needs Improvement | B32: 0
A33: Outstanding | B33: 92304.652
A34: Grand Total | B34: 505914.21
A37: Row Labels | B37: Average of Salary
A38: Finance | B38: 87016.429
A39: Human Resources | B39: 85486.802
A40: Information Technology | B40: 80389.143
A41: Marketing | B41: 85361.075
A42: Operations | B42: 79988.512
A43: Sales | B43: 86103.272
...

Sheet HR Dashboard
R8: =AVERAGE(Raw_Employee_Data!G:G) -> 83485.197
R10: =COUNTA(Raw_Employee_Data!A2:A151) -> 150
R12: =COUNTIF(EmployeeData[EmploymentStatus],"Left")/COUNTA(EmployeeData[EMP ID]) -> 0.16
R14: =SUM(Raw_Employee_Data!M:M) -> 505914.21

Sheet Lookup_Departments
A1: Dept_Code | B1: Department_Name
A2: HR01 | B2: Human Resources
A3: IT02 | B3: Information Technology
A4: FIN03 | B4: Finance
A5: MKT04 | B5: Marketing
A6: SAL05 | B6: Sales
A7: OPS06 | B7: Operations

Sheet Lookup_Performance
A1: Min_Score | B1: Max_Score | C1: Performance_Band | D1: Bonus_Percentage
A2: 0 | B2: 49 | C2: Needs Improvement | D2: 0
A3: 50 | B3: 69 | C3: Developing | D3: 0.02
A4: 70 | B4: 84 | C4: Achieving | D4: 0.05
A5: 85 | B5: 94 | C5: Exceeding | D5: 0.08
A6: 95 | B6: 100 | C6: Outstanding | D6: 0.12
